{"uuid": "a093aa5c-c911-48e6-845b-be76d4c28516", "counter": 16, "stdout": "\u001b[0;31mAn exception occurred during task execution. To see the full traceback, use -vvv. The error was: If you are using a module and expect the file to exist on the remote, see the remote_src option\u001b[0m\r\n\u001b[0;31mfatal: [localhost]: FAILED! => {\"changed\": false, \"msg\": \"Could not find or access '/home/domty/loop_system/generated_data/prefix_for_nmap/2022-11-01.txt' on the Ansible Controller.\\nIf you are using a module and expect the file to exist on the remote, see the remote_src option\"}\u001b[0m", "start_line": 15, "end_line": 17, "runner_ident": "52135446-c151-4703-b8ee-47b22dff83d5", "event": "runner_on_failed", "pid": 20737, "created": "2022-11-01T12:27:49.273611", "parent_uuid": "dc8b282a-80a4-9c33-7054-00000000000f", "event_data": {"playbook": "controller.yaml", "playbook_uuid": "debffe52-531a-4220-ae34-a4b62ddd6de9", "play": "Performing scan", "play_uuid": "dc8b282a-80a4-9c33-7054-000000000009", "play_pattern": "localhost", "task": "Copy prefix_list file to remote server", "task_uuid": "dc8b282a-80a4-9c33-7054-00000000000f", "task_action": "copy", "resolved_action": "ansible.builtin.copy", "task_args": "", "task_path": "/home/domty/loop_system/roles/scan/tasks/main.yaml:36", "role": "scan", "host": "localhost", "remote_addr": "localhost", "res": {"msg": "Could not find or access '/home/domty/loop_system/generated_data/prefix_for_nmap/2022-11-01.txt' on the Ansible Controller.\nIf you are using a module and expect the file to exist on the remote, see the remote_src option", "exception": "Traceback (most recent call last):\n  File \"/home/domty/.local/lib/python3.8/site-packages/ansible/plugins/action/copy.py\", line 466, in run\n    source = self._find_needle('files', source)\n  File \"/home/domty/.local/lib/python3.8/site-packages/ansible/plugins/action/__init__.py\", line 1417, in _find_needle\n    return self._loader.path_dwim_relative_stack(path_stack, dirname, needle)\n  File \"/home/domty/.local/lib/python3.8/site-packages/ansible/parsing/dataloader.py\", line 341, in path_dwim_relative_stack\n    raise AnsibleFileNotFound(file_name=source, paths=[to_native(p) for p in search])\nansible.errors.AnsibleFileNotFound: Could not find or access '/home/domty/loop_system/generated_data/prefix_for_nmap/2022-11-01.txt' on the Ansible Controller.\nIf you are using a module and expect the file to exist on the remote, see the remote_src option\n", "invocation": {"src": "/home/domty/loop_system/generated_data/prefix_for_nmap/2022-11-01.txt", "dest": "/etc/nmap_scan/prefix_list-2022-11-01.txt", "module_args": {"src": "/home/domty/loop_system/generated_data/prefix_for_nmap/2022-11-01.txt", "dest": "/etc/nmap_scan/prefix_list-2022-11-01.txt"}}, "_ansible_no_log": null, "changed": false}, "start": "2022-11-01T12:27:49.057544", "end": "2022-11-01T12:27:49.273266", "duration": 0.215722, "ignore_errors": null, "event_loop": null, "uuid": "a093aa5c-c911-48e6-845b-be76d4c28516"}}